Workbook

Sheet Read me
A1: anthonyis.uk redirect map
A3: What this is | B3: Every URL on the current site, what happens to it on the new site, and why. Source: the live WordPress sitemaps, 16 Oct 2026, plus URLs WordPress serves outside the sitemap. Rows found since are dated in the Added column, and the Changes tab lists every change.
A4: How we work through it | B4: I've proposed an action for every row. You only touch the yellow columns on the URL map tab. Leave 'Your decision' blank to accept my proposal. Pick Keep, 301, 410 or 404 to override. Add 'Your new URL' to change the destination.
A5: What happens next | B5: 1. You settle every 'Decide' row. 2. The Final columns become the site's redirect file (public/_redirects). 3. A test checks every row against the preview site, in one hop, before launch.
A7: Rules for the move
A8: 1. Same URL wherever possible | B8: Every change costs some ranking. The new platform can match any slug, so most rows are Keep.
A9: 2. One hop only | B9: Every old URL goes straight to its final URL. No chains, including the existing /shopify-expert-uk/ redirect.
A10: 3. Closest relevant page | B10: Never send removed pages to the homepage. Google treats that as a soft 404.
A11: 4. 410 for deliberate removals | B11: Tells Google the page is gone on purpose. Faster than a 404.
A12: 5. No other changes during the move | B12: No slug, title, H1 or meta changes in the same release. Do those later, one at a time.
A13: 6. Match today's format | B13: https, no www, trailing slash on every page.
A15: Status
A16: Total rows | B16: =COUNTA('URL map'!C2:C91) -> 90
A17: Final action: Keep | B17: =COUNTIF('URL map'!J2:J91,"Keep") -> 51
A18: Final action: 301 | B18: =COUNTIF('URL map'!J2:J91,"301") -> 12
A19: Final action: 410 | B19: =COUNTIF('URL map'!J2:J91,"410") -> 3
A20: Final action: 404 | B20: =COUNTIF('URL map'!J2:J91,"404") -> 1
A21: Final action: Decide | B21: =COUNTIF('URL map'!J2:J91,"Decide") -> 23

Sheet URL map
A1: # | B1: Section | C1: Current URL | D1: What it is | E1: Proposed action | F1: Proposed new URL | G1: Why | H1: Your decision | I1: Your new URL (optional) | J1: Final action | K1: Final URL | L1: GSC clicks (16 mo) | M1: Referring domains | N1: Added
A2: 1 | B2: Page | C2: / | D2: Homepage | E2: Keep | F2: / | G2: Main ranking page and AI shopfront. Never moves. | J2: =IF(H2="",E2,H2) -> Keep | K2: =IF(J2="410","",IF(J2="404","",IF(I2<>"",I2,F2))) -> / | N2: 16 Oct 2026
A3: 2 | B3: Page | C3: /shopify-website-design/ | D3: Services hub | E3: Keep | F3: /shopify-website-design/ | G3: Keep. New site drops the canonical to the homepage so it can index on its own. | J3: =IF(H3="",E3,H3) -> Keep | K3: =IF(J3="410","",IF(J3="404","",IF(I3<>"",I3,F3))) -> /shopify-website-design/ | N3: 16 Oct 2026
A4: 3 | B4: Page | C4: /shopify-website-design/bespoke-shopify-store-builds/ | D4: Service: Bespoke store design | E4: Keep | F4: /shopify-website-design/bespoke-shopify-store-builds/ | G4: Slug says 'builds' while the service is design. Still keep it: renaming a ranking page costs more than it gains. Revisit after launch. | J4: =IF(H4="",E4,H4) -> Keep | K4: =IF(J4="410","",IF(J4="404","",IF(I4<>"",I4,F4))) -> /shopify-website-design/bespoke-shopify-store-builds/ | N4: 16 Oct 2026
A5: 4 | B5: Page | C5: /shopify-website-design/shopify-theme-customisation/ | D5: Service: Theme customisations | E5: Keep | F5: /shopify-website-design/shopify-theme-customisation/ | J5: =IF(H5="",E5,H5) -> Keep | K5: =IF(J5="410","",IF(J5="404","",IF(I5<>"",I5,F5))) -> /shopify-website-design/shopify-theme-customisation/ | N5: 16 Oct 2026
A6: 5 | B6: Page | C6: /shopify-website-design/shopify-migration/ | D6: Service: Migrations | E6: Keep | F6: /shopify-website-design/shopify-migration/ | G6: Internal link target in case studies. | J6: =IF(H6="",E6,H6) -> Keep | K6: =IF(J6="410","",IF(J6="404","",IF(I6<>"",I6,F6))) -> /shopify-website-design/shopify-migration/ | N6: 16 Oct 2026
A7: 6 | B7: Page | C7: /shopify-website-design/shopify-conversion-rate-optimisation/ | D7: Service: Shopify CRO | E7: Keep | F7: /shopify-website-design/shopify-conversion-rate-optimisation/ | J7: =IF(H7="",E7,H7) -> Keep | K7: =IF(J7="410","",IF(J7="404","",IF(I7<>"",I7,F7))) -> /shopify-website-design/shopify-conversion-rate-optimisation/ | N7: 16 Oct 2026
A8: 7 | B8: Page | C8: /shopify-website-design/shopify-subscriptions/ | D8: Service: Subscriptions | E8: Keep | F8: /shopify-website-design/shopify-subscriptions/ | J8: =IF(H8="",E8,H8) -> Keep | K8: =IF(J8="410","",IF(J8="404","",IF(I8<>"",I8,F8))) -> /shopify-website-design/shopify-subscriptions/ | N8: 16 Oct 2026
A9: 8 | B9: Page | C9: /shopify-website-design/shopify-ai-search-design/ | D9: AI search design page | E9: Keep | F9: /shopify-website-design/shopify-ai-search-design/ | G9: Slug already agreed. | J9: =IF(H9="",E9,H9) -> Keep | K9: =IF(J9="410","",IF(J9="404","",IF(I9<>"",I9,F9))) -> /shopify-website-design/shopify-ai-search-design/ | N9: 16 Oct 2026
A10: 9 | B10: Page | C10: /shopify-website-design/shopify-design-for-dtc-brands/ | D10: DTC brands page | E10: Decide | F10: /shopify-website-design/ | G10: Not one of the eight services, and not on the new site. Keep as an audience landing page, or 301 to the hub. Check its clicks first. 23 Oct: five articles link to it (Shopify UX review, product card design, agentic storefronts, how to design a Shopify website, what DTC brands should look for). Once decided, those links get pointed at the final URL so none hops. | J10: =IF(H10="",E10,H10) -> Decide | K10: =IF(J10="410","",IF(J10="404","",IF(I10<>"",I10,F10))) -> /shopify-website-design/ | N10: 16 Oct 2026
A11: 10 | B11: Page | C11: /freelance-brand-designer/ | D11: Brand designer page | E11: Decide | F11: /shopify-website-design/shopify-branding/ | G11: Maps to the Branding service. Either this URL becomes the Branding page, or 301 it to a new page under the hub. New URL is a placeholder. | J11: =IF(H11="",E11,H11) -> Decide | K11: =IF(J11="410","",IF(J11="404","",IF(I11<>"",I11,F11))) -> /shopify-website-design/shopify-branding/ | N11: 16 Oct 2026
A12: 11 | B12: Page | C12: /freelance-ux-ui-designer/ | D12: UX/UI designer page | E12: Decide | F12: /shopify-website-design/shopify-ux-design/ | G12: Maps to the UX design service. Protect 'Shopify UX designer' rankings. New URL is a placeholder. | J12: =IF(H12="",E12,H12) -> Decide | K12: =IF(J12="410","",IF(J12="404","",IF(I12<>"",I12,F12))) -> /shopify-website-design/shopify-ux-design/ | N12: 16 Oct 2026
A13: 12 | B13: Page | C13: /freelance-motion-graphics-designer/ | D13: Motion graphics page | E13: Decide | F13: /about/ | G13: Off positioning. 301 to About if it has links or clicks, otherwise 410. | J13: =IF(H13="",E13,H13) -> Decide | K13: =IF(J13="410","",IF(J13="404","",IF(I13<>"",I13,F13))) -> /about/ | N13: 16 Oct 2026
A14: 13 | B14: Page | C14: /work/ | D14: Work page | E14: Keep | F14: /work/ | J14: =IF(H14="",E14,H14) -> Keep | K14: =IF(J14="410","",IF(J14="404","",IF(I14<>"",I14,F14))) -> /work/ | N14: 16 Oct 2026
A15: 14 | B15: Page | C15: /about/ | D15: About | E15: Keep | F15: /about/ | J15: =IF(H15="",E15,H15) -> Keep | K15: =IF(J15="410","",IF(J15="404","",IF(I15<>"",I15,F15))) -> /about/ | N15: 16 Oct 2026
A16: 15 | B16: Page | C16: /articles/ | D16: Articles index | E16: Keep | F16: /articles/ | J16: =IF(H16="",E16,H16) -> Keep | K16: =IF(J16="410","",IF(J16="404","",IF(I16<>"",I16,F16))) -> /articles/ | N16: 16 Oct 2026
A17: 16 | B17: Page | C17: /testimonials/ | D17: Testimonials | E17: Decide | F17: /testimonials/ | G17: Keep, or fold into the transparency page. Either way, drop the chatgpt UTM link pointing here. | J17: =IF(H17="",E17,H17) -> Decide | K17: =IF(J17="410","",IF(J17="404","",IF(I17<>"",I17,F17))) -> /testimonials/ | N17: 16 Oct 2026
A18: 17 | B18: Page | C18: /contact/ | D18: Contact | E18: Keep | F18: /contact/ | J18: =IF(H18="",E18,H18) -> Keep | K18: =IF(J18="410","",IF(J18="404","",IF(I18<>"",I18,F18))) -> /contact/ | N18: 16 Oct 2026
A19: 18 | B19: Article | C19: /articles/how-to-design-a-shopify-website-2026/ | D19: How to design a Shopify website | E19: Keep | F19: /articles/how-to-design-a-shopify-website-2026/ | J19: =IF(H19="",E19,H19) -> Keep | K19: =IF(J19="410","",IF(J19="404","",IF(I19<>"",I19,F19))) -> /articles/how-to-design-a-shopify-website-2026/ | N19: 16 Oct 2026
A20: 19 | B20: Article | C20: /articles/what-to-look-for-hiring-shopify-designer/ | D20: What to look for hiring a Shopify designer | E20: Keep | F20: /articles/what-to-look-for-hiring-shopify-designer/ | J20: =IF(H20="",E20,H20) -> Keep | K20: =IF(J20="410","",IF(J20="404","",IF(I20<>"",I20,F20))) -> /articles/what-to-look-for-hiring-shopify-designer/ | N20: 16 Oct 2026
A21: 20 | B21: Article | C21: /articles/shopify-product-card-design/ | D21: Shopify product card design | E21: Keep | F21: /articles/shopify-product-card-design/ | J21: =IF(H21="",E21,H21) -> Keep | K21: =IF(J21="410","",IF(J21="404","",IF(I21<>"",I21,F21))) -> /articles/shopify-product-card-design/ | N21: 16 Oct 2026
A22: 21 | B22: Article | C22: /articles/voice-search-optimisation-for-shopify-stores-a-complete-2025-guide/ | D22: Voice search optimisation | E22: Keep | F22: /articles/voice-search-optimisation-for-shopify-stores-a-complete-2025-guide/ | G22: Keep the year in the slug. Change slugs later, one at a time, never during the move. | J22: =IF(H22="",E22,H22) -> Keep | K22: =IF(J22="410","",IF(J22="404","",IF(I22<>"",I22,F22))) -> /articles/voice-search-optimisation-for-shopify-stores-a-complete-2025-guide/ | N22: 16 Oct 2026
A23: 22 | B23: Article | C23: /articles/shopify-agentic-storefronts/ | D23: Shopify agentic storefronts | E23: Keep | F23: /articles/shopify-agentic-storefronts/ | J23: =IF(H23="",E23,H23) -> Keep | K23: =IF(J23="410","",IF(J23="404","",IF(I23<>"",I23,F23))) -> /articles/shopify-agentic-storefronts/ | N23: 16 Oct 2026
A24: 23 | B24: Article | C24: /articles/generative-engine-optimisation-shopify/ | D24: Generative engine optimisation | E24: Keep | F24: /articles/generative-engine-optimisation-shopify/ | J24: =IF(H24="",E24,H24) -> Keep | K24: =IF(J24="410","",IF(J24="404","",IF(I24<>"",I24,F24))) -> /articles/generative-engine-optimisation-shopify/ | N24: 16 Oct 2026
A25: 24 | B25: Article | C25: /articles/shortlisted-uk-ecommerce-awards-2026/ | D25: Awards article | E25: Keep | F25: /articles/shortlisted-uk-ecommerce-awards-2026/ | J25: =IF(H25="",E25,H25) -> Keep | K25: =IF(J25="410","",IF(J25="404","",IF(I25<>"",I25,F25))) -> /articles/shortlisted-uk-ecommerce-awards-2026/ | N25: 16 Oct 2026
A26: 25 | B26: Article | C26: /articles/25-biggest-brands-using-shopify-in-2025/ | D26: 25 Biggest Brands | E26: Keep | F26: /articles/25-biggest-brands-using-shopify-in-2025/ | G26: Keep the 2025 slug at launch: second biggest AI citation earner, and AI tools keep citing old URLs (Articles strategy doc, 22 Oct). | J26: =IF(H26="",E26,H26) -> Keep | K26: =IF(J26="410","",IF(J26="404","",IF(I26<>"",I26,F26))) -> /articles/25-biggest-brands-using-shopify-in-2025/ | N26: 16 Oct 2026
A27: 26 | B27: Article | C27: /articles/good-conversion-rate-shopify/ | D27: What is a good conversion rate | E27: Keep | F27: /articles/good-conversion-rate-shopify/ | J27: =IF(H27="",E27,H27) -> Keep | K27: =IF(J27="410","",IF(J27="404","",IF(I27<>"",I27,F27))) -> /articles/good-conversion-rate-shopify/ | N27: 16 Oct 2026
A28: 27 | B28: Article | C28: /articles/how-to-increase-conversion-rates-on-your-shopify-store/ | D28: How to increase conversion rates | E28: Keep | F28: /articles/how-to-increase-conversion-rates-on-your-shopify-store/ | J28: =IF(H28="",E28,H28) -> Keep | K28: =IF(J28="410","",IF(J28="404","",IF(I28<>"",I28,F28))) -> /articles/how-to-increase-conversion-rates-on-your-shopify-store/ | N28: 16 Oct 2026
A29: 28 | B29: Article | C29: /articles/strategies-for-your-homeware-lifestyle-shopify-store/ | D29: Homeware and lifestyle strategies | E29: Keep | F29: /articles/strategies-for-your-homeware-lifestyle-shopify-store/ | J29: =IF(H29="",E29,H29) -> Keep | K29: =IF(J29="410","",IF(J29="404","",IF(I29<>"",I29,F29))) -> /articles/strategies-for-your-homeware-lifestyle-shopify-store/ | N29: 16 Oct 2026
A30: 29 | B30: Article | C30: /articles/microinteractions-in-shopify-website-design/ | D30: Microinteractions | E30: Keep | F30: /articles/microinteractions-in-shopify-website-design/ | J30: =IF(H30="",E30,H30) -> Keep | K30: =IF(J30="410","",IF(J30="404","",IF(I30<>"",I30,F30))) -> /articles/microinteractions-in-shopify-website-design/ | N30: 16 Oct 2026
A31: 30 | B31: Article | C31: /articles/shopify-vs-shopify-plus/ | D31: Shopify vs Shopify Plus | E31: Keep | F31: /articles/shopify-vs-shopify-plus/ | G31: Proven lead source. Keep. | J31: =IF(H31="",E31,H31) -> Keep | K31: =IF(J31="410","",IF(J31="404","",IF(I31<>"",I31,F31))) -> /articles/shopify-vs-shopify-plus/ | N31: 16 Oct 2026
A32: 31 | B32: Article | C32: /articles/why-off-the-shelf-shopify-themes-hold-stores-back-in-2025/ | D32: Off-the-shelf themes | E32: Keep | F32: /articles/why-off-the-shelf-shopify-themes-hold-stores-back-in-2025/ | G32: Keep the year in the slug. Change slugs later, one at a time, never during the move. | J32: =IF(H32="",E32,H32) -> Keep | K32: =IF(J32="410","",IF(J32="404","",IF(I32<>"",I32,F32))) -> /articles/why-off-the-shelf-shopify-themes-hold-stores-back-in-2025/ | N32: 16 Oct 2026
A33: 32 | B33: Article | C33: /articles/product-comparisons-for-shopify-stores-how-better-ux-boosts-conversions/ | D33: Product comparisons | E33: Keep | F33: /articles/product-comparisons-for-shopify-stores-how-better-ux-boosts-conversions/ | J33: =IF(H33="",E33,H33) -> Keep | K33: =IF(J33="410","",IF(J33="404","",IF(I33<>"",I33,F33))) -> /articles/product-comparisons-for-shopify-stores-how-better-ux-boosts-conversions/ | N33: 16 Oct 2026
A34: 33 | B34: Article | C34: /articles/shopify-collabs-in-2025-harnessing-the-creator-economy-for-growth/ | D34: Shopify Collabs | E34: Keep | F34: /articles/shopify-collabs-in-2025-harnessing-the-creator-economy-for-growth/ | G34: Keep the year in the slug. Change slugs later, one at a time, never during the move. | J34: =IF(H34="",E34,H34) -> Keep | K34: =IF(J34="410","",IF(J34="404","",IF(I34<>"",I34,F34))) -> /articles/shopify-collabs-in-2025-harnessing-the-creator-economy-for-growth/ | N34: 16 Oct 2026
A35: 34 | B35: Article | C35: /articles/what-makes-a-good-landing-page/ | D35: What makes a good landing page | E35: Keep | F35: /articles/what-makes-a-good-landing-page/ | J35: =IF(H35="",E35,H35) -> Keep | K35: =IF(J35="410","",IF(J35="404","",IF(I35<>"",I35,F35))) -> /articles/what-makes-a-good-landing-page/ | N35: 16 Oct 2026
A36: 35 | B36: Article | C36: /articles/why-conversion-rate-optimisation-is-still-a-human-skill/ | D36: CRO is still a human skill | E36: Keep | F36: /articles/why-conversion-rate-optimisation-is-still-a-human-skill/ | J36: =IF(H36="",E36,H36) -> Keep | K36: =IF(J36="410","",IF(J36="404","",IF(I36<>"",I36,F36))) -> /articles/why-conversion-rate-optimisation-is-still-a-human-skill/ | N36: 16 Oct 2026
A37: 36 | B37: Article | C37: /articles/what-is-a-shopify-partner/ | D37: What is a Shopify Partner | E37: Keep | F37: /articles/what-is-a-shopify-partner/ | J37: =IF(H37="",E37,H37) -> Keep | K37: =IF(J37="410","",IF(J37="404","",IF(I37<>"",I37,F37))) -> /articles/what-is-a-shopify-partner/ | N37: 16 Oct 2026
A38: 37 | B38: Article | C38: /articles/benefits-of-shopify-plus/ | D38: Benefits of Shopify Plus | E38: Keep | F38: /articles/benefits-of-shopify-plus/ | J38: =IF(H38="",E38,H38) -> Keep | K38: =IF(J38="410","",IF(J38="404","",IF(I38<>"",I38,F38))) -> /articles/benefits-of-shopify-plus/ | N38: 16 Oct 2026
A39: 38 | B39: Article | C39: /articles/klaviyo-pricing-2026-complete-breakdown-for-shopify-stores/ | D39: Klaviyo pricing | E39: Keep | F39: /articles/klaviyo-pricing-2026-complete-breakdown-for-shopify-stores/ | J39: =IF(H39="",E39,H39) -> Keep | K39: =IF(J39="410","",IF(J39="404","",IF(I39<>"",I39,F39))) -> /articles/klaviyo-pricing-2026-complete-breakdown-for-shopify-stores/ | N39: 16 Oct 2026
A40: 39 | B40: Article | C40: /articles/what-dtc-brands-should-look-for-shopify-designer/ | D40: What DTC brands should look for | E40: Keep | F40: /articles/what-dtc-brands-should-look-for-shopify-designer/ | J40: =IF(H40="",E40,H40) -> Keep | K40: =IF(J40="410","",IF(J40="404","",IF(I40<>"",I40,F40))) -> /articles/what-dtc-brands-should-look-for-shopify-designer/ | N40: 16 Oct 2026
...

Sheet Changes
A1: Date | B1: Change
A2: 16 Oct 2026 | B2: Map created from the live sitemaps: 80 rows.
A3: 23 Oct 2026 | B3: Moved to Google Drive as the one live copy. Added an Added column.
A4: 23 Oct 2026 | B4: Added rows 81 to 90 from the articles migration: the exact WordPress author and category paths, the old 25 Biggest Brands slug, the three '2025' slug proposals and the DTC article merge (both Decide), and the article images and recordings.
A5: 23 Oct 2026 | B5: Row 9 (DTC brands page): noted the five articles that link to it.
A6: 23 Oct 2026 | B6: Row 25 (25 Biggest Brands): keeps its 2025 slug at launch, per the Articles strategy doc.
A7: 23 Oct 2026 | B7: Row 69 (articles pagination): Decide to Keep, since the new articles page uses the same page 2 address.
